<?xml version="1.0"?>
<robot xmlns:xacro="https://www.ros.org/wiki/xacro">

  <!-- Include external file for color definitions -->
  <xacro:include filename="colours.xacro" />

  <!-- Base link of the robot -->
  <link name="base_link">
  </link>

  <!-- Fixed joint connecting the base link to the chassis -->
  <joint name="chassis_joint" type="fixed">
    <origin xyz="-.1 0 0"/>
    <parent link="base_link"/>
    <child link="chassis"/>
  </joint>

  <!-- Chassis link of the robot -->
  <link name="chassis">
    <visual>
      <origin xyz=".15 0 .075"/>
      <geometry>
        <box size="0.3 0.3 0.15"/>
      </geometry>
      <material name="grey"/>
    </visual>
  </link>

<!-- Left wheel link-->

<joint name="left_wheel_joint" type="continuous">
  <parent link="base_link"/>
  <child link="left_wheel"/>
  <origin xyz="0 0.175 0" rpy ="-${pi/2} 0 0"/>
  <axis xyz="0 0 1"/>
</joint>

<link name="left_wheel">
  <visual>
    <geometry>
      <cylinder radius="0.05" length="0.04"/>
    </geometry>
    <material name="red"/>
  </visual>


<!-- right wheel link-->

<joint name="right_wheel_joint" type="continuous">
  <parent link="base_link"/>
  <child link="right_wheel"/>
  <origin xyz="0 -0.175 0" rpy ="${pi/2} 0 0"/>
  <axis xyz="0 0 -1"/>
</joint>

<link name="right_wheel">
  <visual>
    <geometry>
      <cylinder radius="0.05" length="0.04"/>
    </geometry>
    <material name="red"/>
  </visual>



</robot>